Workbook

Sheet Master data
C1: Consolidation in Excel
C3: Product | E3: Jan | F3: Feb | G3: Mar | H3: Apr | I3: May | J3: Jun | K3: Jul | L3: Aug | M3: Sep | N3: Total
D4: Coffee | E4: ='Q1'!$C$4 -> 1369 | F4: ='Q1'!$D$4 -> 420 | G4: ='Q1'!$E$4 -> 294 | N4: ='Q1'!$F$4 -> 2083
D5: Coffee | H5: ='Q2'!$C$4 -> 187 | I5: ='Q2'!$D$4 -> 513 | J5: ='Q2'!$E$4 -> 430 | N5: ='Q2'!$F$4 -> 1130
D6: Coffee | K6: ='Q3'!$C$4 -> 695 | L6: ='Q3'!$D$4 -> 409 | M6: ='Q3'!$E$4 -> 621 | N6: ='Q3'!$F$4 -> 1725
D7: Coffee | E7: ='Q4'!$C$4 -> 336 | F7: ='Q4'!$D$4 -> 466 | G7: ='Q4'!$E$4 -> 298 | N7: ='Q4'!$F$4 -> 1100
C8: Coffee | E8: =SUM(E4:E7) -> 1705 | F8: =SUM(F4:F7) -> 886 | G8: =SUM(G4:G7) -> 592 | H8: =SUM(H4:H7) -> 187 | I8: =SUM(I4:I7) -> 513 | J8: =SUM(J4:J7) -> 430 | K8: =SUM(K4:K7) -> 695 | L8: =SUM(L4:L7) -> 409 | ... N8: =SUM(N4:N7) -> 6038
D9: Candy | E9: ='Q1'!$C$5 -> 487 | F9: ='Q1'!$D$5 -> 470 | G9: ='Q1'!$E$5 -> 333 | N9: ='Q1'!$F$5 -> 1290
D10: Candy | H10: ='Q2'!$C$5 -> 520 | I10: ='Q2'!$D$5 -> 342 | J10: ='Q2'!$E$5 -> 397 | N10: ='Q2'!$F$5 -> 1259
D11: Candy | K11: ='Q3'!$C$5 -> 505 | L11: ='Q3'!$D$5 -> 290 | M11: ='Q3'!$E$5 -> 582 | N11: ='Q3'!$F$5 -> 1377
D12: Candy | E12: ='Q4'!$C$5 -> 662 | F12: ='Q4'!$D$5 -> 556 | G12: ='Q4'!$E$5 -> 365 | N12: ='Q4'!$F$5 -> 1583
C13: Candy | E13: =SUM(E9:E12) -> 1149 | F13: =SUM(F9:F12) -> 1026 | G13: =SUM(G9:G12) -> 698 | H13: =SUM(H9:H12) -> 520 | I13: =SUM(I9:I12) -> 342 | J13: =SUM(J9:J12) -> 397 | K13: =SUM(K9:K12) -> 505 | L13: =SUM(L9:L12) -> 290 | ... N13: =SUM(N9:N12) -> 5509
D14: Book3 | E14: ='Q1'!$C$6 -> 498 | F14: ='Q1'!$D$6 -> 486 | G14: ='Q1'!$E$6 -> 302 | N14: ='Q1'!$F$6 -> 1286
D15: Book3 | H15: ='Q2'!$C$6 -> 143 | I15: ='Q2'!$D$6 -> 102 | J15: ='Q2'!$E$6 -> 228 | N15: ='Q2'!$F$6 -> 473
D16: Book3 | K16: ='Q3'!$C$6 -> 516 | L16: ='Q3'!$D$6 -> 495 | M16: ='Q3'!$E$6 -> 677 | N16: ='Q3'!$F$6 -> 1688
D17: Book3 | E17: ='Q4'!$C$6 -> 243 | F17: ='Q4'!$D$6 -> 495 | G17: ='Q4'!$E$6 -> 253 | N17: ='Q4'!$F$6 -> 991
C18: Chocolate | E18: =SUM(E14:E17) -> 741 | F18: =SUM(F14:F17) -> 981 | G18: =SUM(G14:G17) -> 555 | H18: =SUM(H14:H17) -> 143 | I18: =SUM(I14:I17) -> 102 | J18: =SUM(J14:J17) -> 228 | K18: =SUM(K14:K17) -> 516 | L18: =SUM(L14:L17) -> 495 | ... N18: =SUM(N14:N17) -> 4438 | Q18: Data > Consolidate
D19: Book3 | E19: ='Q1'!$C$7 -> 327 | F19: ='Q1'!$D$7 -> 432 | G19: ='Q1'!$E$7 -> 292 | N19: ='Q1'!$F$7 -> 1051
D20: Book3 | H20: ='Q2'!$C$7 -> 429 | I20: ='Q2'!$D$7 -> 300 | J20: ='Q2'!$E$7 -> 334 | N20: ='Q2'!$F$7 -> 1063
D21: Book3 | K21: ='Q3'!$C$7 -> 692 | L21: ='Q3'!$D$7 -> 515 | M21: ='Q3'!$E$7 -> 208 | N21: ='Q3'!$F$7 -> 1415
D22: Book3 | E22: ='Q4'!$C$7 -> 490 | F22: ='Q4'!$D$7 -> 117 | G22: ='Q4'!$E$7 -> 590 | N22: ='Q4'!$F$7 -> 1197
C23: Sugar | E23: =SUM(E19:E22) -> 817 | F23: =SUM(F19:F22) -> 549 | G23: =SUM(G19:G22) -> 882 | H23: =SUM(H19:H22) -> 429 | I23: =SUM(I19:I22) -> 300 | J23: =SUM(J19:J22) -> 334 | K23: =SUM(K19:K22) -> 692 | L23: =SUM(L19:L22) -> 515 | ... N23: =SUM(N19:N22) -> 4726
D24: Book3 | E24: ='Q1'!$C$8 -> 394 | F24: ='Q1'!$D$8 -> 254 | G24: ='Q1'!$E$8 -> 244 | N24: ='Q1'!$F$8 -> 892
D25: Book3 | H25: ='Q2'!$C$8 -> 335 | I25: ='Q2'!$D$8 -> 173 | J25: ='Q2'!$E$8 -> 542 | N25: ='Q2'!$F$8 -> 1050
D26: Book3 | K26: ='Q3'!$C$8 -> 621 | L26: ='Q3'!$D$8 -> 643 | M26: ='Q3'!$E$8 -> 477 | N26: ='Q3'!$F$8 -> 1741
D27: Book3 | E27: ='Q4'!$C$8 -> 176 | F27: ='Q4'!$D$8 -> 336 | G27: ='Q4'!$E$8 -> 296 | N27: ='Q4'!$F$8 -> 808
C28: Milk Powder | E28: =SUM(E24:E27) -> 570 | F28: =SUM(F24:F27) -> 590 | G28: =SUM(G24:G27) -> 540 | H28: =SUM(H24:H27) -> 335 | I28: =SUM(I24:I27) -> 173 | J28: =SUM(J24:J27) -> 542 | K28: =SUM(K24:K27) -> 621 | L28: =SUM(L24:L27) -> 643 | ... N28: =SUM(N24:N27) -> 4491
D29: Book3 | E29: ='Q1'!$C$9 -> 272 | F29: ='Q1'!$D$9 -> 372 | G29: ='Q1'!$E$9 -> 360 | N29: ='Q1'!$F$9 -> 1004
D30: Book3 | H30: ='Q2'!$C$9 -> 420 | I30: ='Q2'!$D$9 -> 360 | J30: ='Q2'!$E$9 -> 361 | N30: ='Q2'!$F$9 -> 1141
D31: Book3 | K31: ='Q3'!$C$9 -> 461 | L31: ='Q3'!$D$9 -> 379 | M31: ='Q3'!$E$9 -> 282 | N31: ='Q3'!$F$9 -> 1122
D32: Book3 | E32: ='Q4'!$C$9 -> 561 | F32: ='Q4'!$D$9 -> 702 | G32: ='Q4'!$E$9 -> 171 | N32: ='Q4'!$F$9 -> 1434
C33: Biscuits | E33: =SUM(E29:E32) -> 833 | F33: =SUM(F29:F32) -> 1074 | G33: =SUM(G29:G32) -> 531 | H33: =SUM(H29:H32) -> 420 | I33: =SUM(I29:I32) -> 360 | J33: =SUM(J29:J32) -> 361 | K33: =SUM(K29:K32) -> 461 | L33: =SUM(L29:L32) -> 379 | ... N33: =SUM(N29:N32) -> 4701
D34: Book3 | E34: ='Q1'!$C$10 -> 455 | F34: ='Q1'!$D$10 -> 218 | G34: ='Q1'!$E$10 -> 287 | N34: ='Q1'!$F$10 -> 960
D35: Book3 | H35: ='Q2'!$C$10 -> 230 | I35: ='Q2'!$D$10 -> 539 | J35: ='Q2'!$E$10 -> 114 | N35: ='Q2'!$F$10 -> 883
D36: Book3 | K36: ='Q3'!$C$10 -> 409 | L36: ='Q3'!$D$10 -> 309 | M36: ='Q3'!$E$10 -> 539 | N36: ='Q3'!$F$10 -> 1257
D37: Book3 | E37: ='Q4'!$C$10 -> 322 | F37: ='Q4'!$D$10 -> 450 | G37: ='Q4'!$E$10 -> 656 | N37: ='Q4'!$F$10 -> 1428
C38: Cold Drinks | E38: =SUM(E34:E37) -> 777 | F38: =SUM(F34:F37) -> 668 | G38: =SUM(G34:G37) -> 943 | H38: =SUM(H34:H37) -> 230 | I38: =SUM(I34:I37) -> 539 | J38: =SUM(J34:J37) -> 114 | K38: =SUM(K34:K37) -> 409 | L38: =SUM(L34:L37) -> 309 | ... N38: =SUM(N34:N37) -> 4528
D39: Book3 | E39: ='Q1'!$C$11 -> 346 | F39: ='Q1'!$D$11 -> 383 | G39: ='Q1'!$E$11 -> 291 | N39: ='Q1'!$F$11 -> 1020
D40: Book3 | H40: ='Q2'!$C$11 -> 254 | I40: ='Q2'!$D$11 -> 561 | J40: ='Q2'!$E$11 -> 365 | N40: ='Q2'!$F$11 -> 1180
D41: Book3 | K41: ='Q3'!$C$11 -> 608 | L41: ='Q3'!$D$11 -> 444 | M41: ='Q3'!$E$11 -> 237 | N41: ='Q3'!$F$11 -> 1289
...

Sheet Q1
A1: Q1
B2: ABC Enterprises
B3: Product | C3: Jan | D3: Feb | E3: Mar | F3: Total
B4: Coffee | C4: 1369 | D4: 420 | E4: 294 | F4: =SUM(C4:E4) -> 2083
B5: Candy | C5: 487 | D5: 470 | E5: 333 | F5: =SUM(C5:E5) -> 1290
B6: Chocolate | C6: 498 | D6: 486 | E6: 302 | F6: =SUM(C6:E6) -> 1286
B7: Sugar | C7: 327 | D7: 432 | E7: 292 | F7: =SUM(C7:E7) -> 1051
B8: Milk Powder | C8: 394 | D8: 254 | E8: 244 | F8: =SUM(C8:E8) -> 892
B9: Biscuits | C9: 272 | D9: 372 | E9: 360 | F9: =SUM(C9:E9) -> 1004
B10: Cold Drinks | C10: 455 | D10: 218 | E10: 287 | F10: =SUM(C10:E10) -> 960
B11: Energy Drink | C11: 346 | D11: 383 | E11: 291 | F11: =SUM(C11:E11) -> 1020
B12: Fruit Juice | C12: 475 | D12: 393 | E12: 206 | F12: =SUM(C12:E12) -> 1074
B13: Total | C13: =SUM(C4:C12) -> 4623 | D13: =SUM(D4:D12) -> 3428 | E13: =SUM(E4:E12) -> 2609 | F13: =SUM(F4:F12) -> 10660

Sheet Q2
A1: Q2
B2: ABC Enterprises
B3: Product | C3: Apr | D3: May | E3: Jun | F3: Total
B4: Coffee | C4: 187 | D4: 513 | E4: 430 | F4: =SUM(C4:E4) -> 1130
B5: Candy | C5: 520 | D5: 342 | E5: 397 | F5: =SUM(C5:E5) -> 1259
B6: Chocolate | C6: 143 | D6: 102 | E6: 228 | F6: =SUM(C6:E6) -> 473
B7: Sugar | C7: 429 | D7: 300 | E7: 334 | F7: =SUM(C7:E7) -> 1063
B8: Milk Powder | C8: 335 | D8: 173 | E8: 542 | F8: =SUM(C8:E8) -> 1050
B9: Biscuits | C9: 420 | D9: 360 | E9: 361 | F9: =SUM(C9:E9) -> 1141
B10: Cold Drinks | C10: 230 | D10: 539 | E10: 114 | F10: =SUM(C10:E10) -> 883
B11: Energy Drink | C11: 254 | D11: 561 | E11: 365 | F11: =SUM(C11:E11) -> 1180
B12: Fruit Juice | C12: 581 | D12: 586 | E12: 332 | F12: =SUM(C12:E12) -> 1499
B13: Total | C13: =SUM(C4:C12) -> 3099 | D13: =SUM(D4:D12) -> 3476 | E13: =SUM(E4:E12) -> 3103 | F13: =SUM(F4:F12) -> 9678

Sheet Q3
A1: Q3
B2: ABC Enterprises
B3: Product | C3: Jul | D3: Aug | E3: Sep | F3: Total
B4: Coffee | C4: 695 | D4: 409 | E4: 621 | F4: =SUM(C4:E4) -> 1725
B5: Candy | C5: 505 | D5: 290 | E5: 582 | F5: =SUM(C5:E5) -> 1377
B6: Chocolate | C6: 516 | D6: 495 | E6: 677 | F6: =SUM(C6:E6) -> 1688
B7: Sugar | C7: 692 | D7: 515 | E7: 208 | F7: =SUM(C7:E7) -> 1415
B8: Milk Powder | C8: 621 | D8: 643 | E8: 477 | F8: =SUM(C8:E8) -> 1741
B9: Biscuits | C9: 461 | D9: 379 | E9: 282 | F9: =SUM(C9:E9) -> 1122
B10: Cold Drinks | C10: 409 | D10: 309 | E10: 539 | F10: =SUM(C10:E10) -> 1257
B11: Energy Drink | C11: 608 | D11: 444 | E11: 237 | F11: =SUM(C11:E11) -> 1289
B12: Fruit Juice | C12: 579 | D12: 655 | E12: 412 | F12: =SUM(C12:E12) -> 1646
B13: Total | C13: =SUM(C4:C12) -> 5086 | D13: =SUM(D4:D12) -> 4139 | E13: =SUM(E4:E12) -> 4035 | F13: =SUM(F4:F12) -> 13260

Sheet Q4
A1: Q4
B2: ABC Enterprises
B3: Product | C3: Jan | D3: Feb | E3: Mar | F3: Total
B4: Coffee | C4: 336 | D4: 466 | E4: 298 | F4: =SUM(C4:E4) -> 1100
B5: Candy | C5: 662 | D5: 556 | E5: 365 | F5: =SUM(C5:E5) -> 1583
B6: Chocolate | C6: 243 | D6: 495 | E6: 253 | F6: =SUM(C6:E6) -> 991
B7: Sugar | C7: 490 | D7: 117 | E7: 590 | F7: =SUM(C7:E7) -> 1197
B8: Milk Powder | C8: 176 | D8: 336 | E8: 296 | F8: =SUM(C8:E8) -> 808
B9: Biscuits | C9: 561 | D9: 702 | E9: 171 | F9: =SUM(C9:E9) -> 1434
B10: Cold Drinks | C10: 322 | D10: 450 | E10: 656 | F10: =SUM(C10:E10) -> 1428
B11: Energy Drink | C11: 446 | D11: 529 | E11: 563 | F11: =SUM(C11:E11) -> 1538
B12: Fruit Juice | C12: 462 | D12: 635 | E12: 296 | F12: =SUM(C12:E12) -> 1393
B13: Total | C13: =SUM(C4:C12) -> 3698 | D13: =SUM(D4:D12) -> 4286 | E13: =SUM(E4:E12) -> 3488 | F13: =SUM(F4:F12) -> 11472
